Internal Server Error: /admin/blog/post/add/
Traceback (most recent call last):
  File "/home/dima/Desktop/test/testenv/local/lib/python2.7/site-packages/django/core/handlers/exception.py", line 41, in inner
    response = get_response(request)
  File "/home/dima/Desktop/test/testenv/local/lib/python2.7/site-packages/django/core/handlers/base.py", line 187, in _get_response
    response = self.process_exception_by_middleware(e, request)
  File "/home/dima/Desktop/test/testenv/local/lib/python2.7/site-packages/django/core/handlers/base.py", line 185, in _get_response
    response = wrapped_callback(request, *callback_args, **callback_kwargs)
  File "/home/dima/Desktop/test/testenv/local/lib/python2.7/site-packages/django/contrib/admin/options.py", line 551, in wrapper
    return self.admin_site.admin_view(view)(*args, **kwargs)
  File "/home/dima/Desktop/test/testenv/local/lib/python2.7/site-packages/django/utils/decorators.py", line 149, in _wrapped_view
    response = view_func(request, *args, **kwargs)
  File "/home/dima/Desktop/test/testenv/local/lib/python2.7/site-packages/django/views/decorators/cache.py", line 57, in _wrapped_view_func
    response = view_func(request, *args, **kwargs)
  File "/home/dima/Desktop/test/testenv/local/lib/python2.7/site-packages/django/contrib/admin/sites.py", line 224, in inner
    return view(request, *args, **kwargs)
  File "/home/dima/Desktop/test/testenv/local/lib/python2.7/site-packages/django/contrib/admin/options.py", line 1508, in add_view
    return self.changeform_view(request, None, form_url, extra_context)
  File "/home/dima/Desktop/test/testenv/local/lib/python2.7/site-packages/django/utils/decorators.py", line 67, in _wrapper
    return bound_func(*args, **kwargs)
  File "/home/dima/Desktop/test/testenv/local/lib/python2.7/site-packages/django/utils/decorators.py", line 149, in _wrapped_view
    response = view_func(request, *args, **kwargs)
  File "/home/dima/Desktop/test/testenv/local/lib/python2.7/site-packages/django/utils/decorators.py", line 63, in bound_func
    return func.__get__(self, type(self))(*args2, **kwargs2)
  File "/home/dima/Desktop/test/testenv/local/lib/python2.7/site-packages/django/contrib/admin/options.py", line 1408, in changeform_view
    return self._changeform_view(request, object_id, form_url, extra_context)
  File "/home/dima/Desktop/test/testenv/local/lib/python2.7/site-packages/django/contrib/admin/options.py", line 1448, in _changeform_view
    self.save_model(request, new_object, form, not add)
  File "/home/dima/Desktop/test/testenv/local/lib/python2.7/site-packages/django/contrib/admin/options.py", line 979, in save_model
    obj.save()
  File "/home/dima/Desktop/test/testenv/local/lib/python2.7/site-packages/django/db/models/base.py", line 807, in save
    force_update=force_update, update_fields=update_fields)
  File "/home/dima/Desktop/test/testenv/local/lib/python2.7/site-packages/django/db/models/base.py", line 837, in save_base
    updated = self._save_table(raw, cls, force_insert, force_update, using, update_fields)
  File "/home/dima/Desktop/test/testenv/local/lib/python2.7/site-packages/django/db/models/base.py", line 923, in _save_table
    result = self._do_insert(cls._base_manager, using, fields, update_pk, raw)
  File "/home/dima/Desktop/test/testenv/local/lib/python2.7/site-packages/django/db/models/base.py", line 962, in _do_insert
    using=using, raw=raw)
  File "/home/dima/Desktop/test/testenv/local/lib/python2.7/site-packages/django/db/models/manager.py", line 85, in manager_method
    return getattr(self.get_queryset(), name)(*args, **kwargs)
  File "/home/dima/Desktop/test/testenv/local/lib/python2.7/site-packages/django/db/models/query.py", line 1076, in _insert
    return query.get_compiler(using=using).execute_sql(return_id)
  File "/home/dima/Desktop/test/testenv/local/lib/python2.7/site-packages/django/db/models/sql/compiler.py", line 1107, in execute_sql
    cursor.execute(sql, params)
  File "/home/dima/Desktop/test/testenv/local/lib/python2.7/site-packages/django/db/backends/utils.py", line 80, in execute
    return super(CursorDebugWrapper, self).execute(sql, params)
  File "/home/dima/Desktop/test/testenv/local/lib/python2.7/site-packages/django/db/backends/utils.py", line 65, in execute
    return self.cursor.execute(sql, params)
  File "/home/dima/Desktop/test/testenv/local/lib/python2.7/site-packages/django/db/utils.py", line 94, in __exit__
    six.reraise(dj_exc_type, dj_exc_value, traceback)
  File "/home/dima/Desktop/test/testenv/local/lib/python2.7/site-packages/django/db/backends/utils.py", line 65, in execute
    return self.cursor.execute(sql, params)
IntegrityError: null value in column "user_id" violates not-null constraint
DETAIL:  Failing row contains (41, Петька, ротттк, 2018-01-31 08:10:06+00, null).

